<?xml version="1.0" encoding="UTF-8"?>
<!-- Generated by org.testng.reporters.JUnitXMLReporter -->
<testsuite ignored="0" hostname="LAPTOP-EA4CD3Q6" failures="2" tests="5" name="Testfailed1" time="0.098" errors="0" timestamp="2021-11-18T13:50:33 IST">
  <testcase classname="failed_test_cases2.Failed_test_cases_run2" name="Abc" time="0.016">
    <failure type="java.lang.AssertionError">
      <![CDATA[java.lang.AssertionError
at org.junit.Assert.fail(Assert.java:86)
at org.junit.Assert.fail(Assert.java:95)
at failed_test_cases2.Failed_test_cases_run2.Abc(Failed_test_cases_run2.java:15)
at java.base/java.util.concurrent.ThreadPoolExecutor.runWorker(ThreadPoolExecutor.java:1130)
at java.base/java.util.concurrent.ThreadPoolExecutor$Worker.run(ThreadPoolExecutor.java:630)
at java.base/java.lang.Thread.run(Thread.java:831)
... Removed 12 stack frames]]>
    </failure>
  </testcase> <!-- Abc -->
  <testcase classname="failed_test_cases2.Failed_test_cases_run2" name="def" time="0.002"/>
  <testcase classname="failed_test_cases2.Failed_test_cases_run2" name="mno" time="0.002">
    <failure type="java.lang.AssertionError">
      <![CDATA[java.lang.AssertionError
at org.junit.Assert.fail(Assert.java:86)
at org.junit.Assert.fail(Assert.java:95)
at failed_test_cases2.Failed_test_cases_run2.mno(Failed_test_cases_run2.java:10)
at java.base/java.util.concurrent.ThreadPoolExecutor.runWorker(ThreadPoolExecutor.java:1130)
at java.base/java.util.concurrent.ThreadPoolExecutor$Worker.run(ThreadPoolExecutor.java:630)
at java.base/java.lang.Thread.run(Thread.java:831)
... Removed 12 stack frames]]>
    </failure>
  </testcase> <!-- mno -->
  <testcase classname="failed_test_cases2.Failed_test_cases_run2" name="pqr" time="0.003"/>
  <testcase classname="failed_test_cases2.Failed_test_cases_run2" name="xyz" time="0.003"/>
</testsuite> <!-- Testfailed1 -->
