<?xml version="1.0" encoding="UTF-8"?>
<!-- Generated by org.testng.reporters.JUnitXMLReporter -->
<testsuite ignored="6" hostname="LAPTOP-EA4CD3Q6" failures="4" tests="4" name="Test(failed)" time="0.084" errors="0" timestamp="2021-11-18T14:15:15 IST">
  <testcase classname="failed_test_cases2.Failed_test_cases_run2" name="mno" time="0.017">
    <failure type="java.lang.AssertionError">
      <![CDATA[java.lang.AssertionError
at org.junit.Assert.fail(Assert.java:86)
at org.junit.Assert.fail(Assert.java:95)
at failed_test_cases2.Failed_test_cases_run2.mno(Failed_test_cases_run2.java:10)
at java.base/java.util.concurrent.ThreadPoolExecutor.runWorker(ThreadPoolExecutor.java:1130)
at java.base/java.util.concurrent.ThreadPoolExecutor$Worker.run(ThreadPoolExecutor.java:630)
at java.base/java.lang.Thread.run(Thread.java:831)
... Removed 12 stack frames]]>
    </failure>
  </testcase> <!-- mno -->
  <testcase classname="failedTestCases.Failed_testcases_run" name="test22" time="0.017">
    <failure type="java.lang.AssertionError">
      <![CDATA[java.lang.AssertionError
at org.junit.Assert.fail(Assert.java:86)
at org.junit.Assert.fail(Assert.java:95)
at failedTestCases.Failed_testcases_run.test22(Failed_testcases_run.java:14)
at java.base/java.util.concurrent.ThreadPoolExecutor.runWorker(ThreadPoolExecutor.java:1130)
at java.base/java.util.concurrent.ThreadPoolExecutor$Worker.run(ThreadPoolExecutor.java:630)
at java.base/java.lang.Thread.run(Thread.java:831)
... Removed 12 stack frames]]>
    </failure>
  </testcase> <!-- test22 -->
  <testcase classname="failed_test_cases2.Failed_test_cases_run2" name="Abc" time="0.003">
    <failure type="java.lang.AssertionError">
      <![CDATA[java.lang.AssertionError
at org.junit.Assert.fail(Assert.java:86)
at org.junit.Assert.fail(Assert.java:95)
at failed_test_cases2.Failed_test_cases_run2.Abc(Failed_test_cases_run2.java:15)
at java.base/java.util.concurrent.ThreadPoolExecutor.runWorker(ThreadPoolExecutor.java:1130)
at java.base/java.util.concurrent.ThreadPoolExecutor$Worker.run(ThreadPoolExecutor.java:630)
at java.base/java.lang.Thread.run(Thread.java:831)
... Removed 12 stack frames]]>
    </failure>
  </testcase> <!-- Abc -->
  <testcase classname="failedTestCases.Failed_testcases_run" name="test23" time="0.009">
    <failure type="java.lang.AssertionError">
      <![CDATA[java.lang.AssertionError
at org.junit.Assert.fail(Assert.java:86)
at org.junit.Assert.fail(Assert.java:95)
at failedTestCases.Failed_testcases_run.test23(Failed_testcases_run.java:19)
at java.base/java.util.concurrent.ThreadPoolExecutor.runWorker(ThreadPoolExecutor.java:1130)
at java.base/java.util.concurrent.ThreadPoolExecutor$Worker.run(ThreadPoolExecutor.java:630)
at java.base/java.lang.Thread.run(Thread.java:831)
... Removed 12 stack frames]]>
    </failure>
  </testcase> <!-- test23 -->
  <testcase classname="failed_test_cases2.Failed_test_cases_run2" name="pqr" time="0.0">
    <ignored/>
  </testcase> <!-- pqr -->
  <testcase classname="failedTestCases.Failed_testcases_run" name="test25" time="0.0">
    <ignored/>
  </testcase> <!-- test25 -->
  <testcase classname="failed_test_cases2.Failed_test_cases_run2" name="def" time="0.0">
    <ignored/>
  </testcase> <!-- def -->
  <testcase classname="failedTestCases.Failed_testcases_run" name="test21" time="0.0">
    <ignored/>
  </testcase> <!-- test21 -->
  <testcase classname="failed_test_cases2.Failed_test_cases_run2" name="xyz" time="0.0">
    <ignored/>
  </testcase> <!-- xyz -->
  <testcase classname="failedTestCases.Failed_testcases_run" name="test24" time="0.0">
    <ignored/>
  </testcase> <!-- test24 -->
</testsuite> <!-- Test(failed) -->
